Workbook

Sheet Info
A1: In the sheets the needed input data for p2Home are collected. The sheets have the following structure: In the PARAMETERS section, parameter names are defined and a description is given. Parameter names should never be changed! In the SCENARIO VALUES sections the values for each parameter can be defined for different scenarios. The defined scenarios must be the same in all sheets! The maximum supported number of scenarios is 10.
A3: Green sheets mark sheets where usually input data should be provided.
A4: Yellow sheets mark sheets where only advanced users should change data.
A5: Grey sheets are not meant to be modified.
A6: Important input parameters are marked in red. For other parameters default values can be used.
A9: Sheet | B9: Description
A10: Location | B10: Location (latitude, longitude) and reference heating temperature
A11: Consumption Data | B11: Data on household size, energy consumption (electricity, heating, hot water) and EV charging
A12: Building Data | B12: Data on heated area and orientation and size of roof/wall areas, windows
A13: Technical Component Data | B13: Data on technical aspects and cost of energy system components: PV, Solar thermal, battery storage, heatpumps, AC, boilers, hot water storages, refurbishment measures
A14: Economic Data | B14: Interest rate, costs of electricity and CO2 price
A15: Model Settings | B15: Settings on climate data years to be considered and timeseries reduction
A16: HP Specifications | B16: COP and Qmax specifications for selected heatpump models
A17: Definitions | B17: Definitions for prefilled fields in other sheets

Sheet Location
A1: PARAMETERS | F1: SCENARIO VALUES
A2: name | B2: description | C2: unit | D2: comment | E2: datatype | F2: BAU | G2: PV + HP | H2: Refurbished | I2: Flex
A3: latitude | B3: latitude of building location | C3: ° | E3: float | F3: 48.4 | G3: =$F$3 -> 48.4 | H3: =$F$3 -> 48.4 | I3: =$F$3 -> 48.4
A4: longitude | B4: logitude of building location ° | C4: ° | E4: float | F4: 11.738 | G4: =$F$4 -> 11.738 | H4: =$F$4 -> 11.738 | I4: =$F$4 -> 11.738
A5: T_out_ref | B5: reference outside temperature for dimensioning heating system | C5: °C | D5: https://www.waermepumpe.de/werkzeuge/klimakarte/ | E5: float | F5: -13.5 | G5: =$F$5 -> -13.5 | H5: =$F$5 -> -13.5 | I5: =$F$5 -> -13.5

Sheet Consumption Data
A1: =Location!A1 -> PARAMETERS | F1: =Location!F1 -> SCENARIO VALUES
A2: name | B2: description | C2: unit | D2: comment | E2: datatype | F2: =Location!F2 -> BAU | G2: =Location!G2 -> PV + HP | H2: =Location!H2 -> Refurbished | I2: =Location!I2 -> Flex | P2: Your specific energy consumption (kWh/m2a) | T2: =F17/'Building Data'!F5 -> 148.64865
A3: general data | P3: Energy efficiency class | T3: =IF(T2<30,"A+", IF(T2<50,"A", IF(T2<75,"B", IF(T2<100,"C", IF(T2<130,"D", IF(T2<160,"E", IF(T2<200,"F", IF(T2<250,"G", "H")))))))) -> E
A4: nr_of_households | B4: number of households in building | D4: obligatory | E4: float | F4: 4 | G4: 4 | H4: 4 | I4: 4
A5: nr_of_persons | B5: number of persons living in the building in total | D5: obligatory | E5: float | F5: 8 | G5: 8 | H5: 8 | I5: 8
A6: electricity consumption
A7: p_el_imp_max | B7: maximum power rating of house connection | C7: kW | E7: float | F7: 30 | G7: 30 | H7: 30 | I7: 30
A8: el_demand | B8: total annual electricity consumptions of all households | C8: kWh | D8: obligatory | E8: float | F8: 8000 | G8: 8000 | H8: 8000 | I8: 8000
A9: nr_of_synPro_hh_1 | B9: number of fulltime employee housholds | C9: - | D9: obligatory | E9: float | F9: 2 | G9: 2 | H9: 2 | I9: 2 | S9: A+ | T9: 30
A10: nr_of_synPro_hh_2 | B10: number of housholds with persons over 65 (retired) | C10: - | D10: obligatory | E10: float | F10: 0 | G10: 0 | H10: 0 | I10: 0 | S10: A | T10: 50
A11: nr_of_synPro_hh_3 | B11: number of familiy households (or homeoffice) | C11: - | D11: obligatory | E11: float | F11: 1 | G11: 1 | H11: 1 | I11: 1 | S11: B | T11: 75
A12: nr_of_synPro_hh_4 | B12: number of households with single persons under 30 (student) | C12: - | D12: obligatory | E12: float | F12: 1 | G12: 1 | H12: 1 | I12: 1 | S12: C | T12: 100
A13: hot water demand | S13: D | T13: 130
A14: l_per_person_day | B14: demand of hot water per person per day | C14: l | D14: obligatory | E14: float | F14: 40 | G14: 40 | H14: 40 | I14: 40 | S14: E | T14: 160
A15: temp_dhw | B15: temperature of domestic hot water | C15: °C | D15: obilgatory | E15: float | F15: 65 | G15: 65 | H15: 65 | I15: 65 | S15: F | T15: 200
A16: heating demand | S16: G | T16: 250
A17: heat_demand | B17: total annual heat consumption of all households (gas/oil) | C17: kWh | D17: if not given, transmission losses need to be given | E17: float | F17: 55000 | G17: 55000 | H17: 55000 | I17: 55000 | S17: H | T17: 300
A18: avg_indoor_temp | B18: indoor temperature averaged over all rooms | C18: °C | D18: obligatory | E18: float | F18: 20 | G18: 20 | H18: 20 | I18: 20
A19: avg_indoor_temp_night | B19: indoor temperature during the night | C19: °C | D19: is equal to day temp. If not given | E19: float | F19: 16 | G19: 16 | H19: 16 | I19: 16
A20: night_period | B20: period during which night temperature is applied | C20: HH-HH | D20: e.g. 0-6 | E20: str | F20: 0-6 | G20: 0-6 | H20: 0-6 | I20: 0-6
A21: heating_threshold | B21: if heating threshold is applied, a heating demand is only calculated for days which have an average temperature lower than the threshold | C21: °C | D21: if none is given, no heating threshold is applied | E21: float | F21: 15 | G21: 15 | H21: 15 | I21: 15
A22: delta_temp_max | B22: indoor temperature tolerance | C22: °C | D22: in a smart controlled building thermal inertia can be used as a buffer storage to provide felxibility, leads to losses in thermal comfort. Delta_temp_max = 2 means that builing can be pre-heated by 2°C | E22: float | F22: 0.5 | G22: 0.5 | H22: 0.5 | I22: 0.5
A23: flow_temp_ref | B23: flow temperature in heating system for reference outside temperature | C23: °C | D23: obligatory | E23: float | F23: 55 | G23: 55 | H23: 55 | I23: 55
A24: e-mobility demand
A25: ev1_max_p | B25: maximum power of charging process | C25: kW | D25: obligatory, if used | E25: float | F25: 20 | G25: 20 | H25: 20 | I25: 20
A26: ev1_period | B26: period when EV is connected to charging column, e.g. 18 - 7 | D26: obligatory, if used | E26: str | F26: 18-7 | G26: 18-7 | H26: 18-7 | I26: 18-7
A27: ev1_drivedist | B27: distance driven with one charge | C27: km | D27: obligatory, if used | E27: float | F27: 50 | G27: 50 | H27: 50 | I27: 50
A28: ev1_kwhper100km | B28: average consumption of electric vehicle | C28: kWh/100km | D28: obligatory, if used | E28: float | F28: 20 | G28: 20 | H28: 20 | I28: 20
A29: ev1_daysinweek | B29: days of week where EV is charged (1: Monday, 7: Sunday) | C29: comma-separated list of values between 1..7 (1=Monday), e.g. '1,2,3,4,5' | D29: obligatory, if used | E29: str | F29: 1,2,3,4,5 | G29: 1,2,3,4,5 | H29: 1,2,3,4,5 | I29: 1,2,3,4,5
A30: ev1_chargetype | B30: charging type: can be fast (with maximum power), flat (constant within period) or optimized (cost-optimized, s.t. battery is full when car leaves charger) | D30: obligatory, if used | E30: str | F30: optimized | G30: optimized | H30: optimized | I30: optimized
A31: ev2_max_p | B31: maximum power of charging process | C31: kW | D31: obligatory, if used | E31: float | F31: 20 | G31: 20 | H31: 20 | I31: 20
A32: ev2_period | B32: period when EV is connected to charging column, e.g. 18 - 7 | D32: obligatory, if used | E32: str | F32: 18-7 | G32: 18-7 | H32: 18-7 | I32: 18-7
A33: ev2_drivedist | B33: distance driven with one charge | C33: km | D33: obligatory, if used | E33: float | F33: 50 | G33: 50 | H33: 50 | I33: 50
A34: ev2_kwhper100km | B34: average consumption of electric vehicle | C34: kWh/100km | D34: obligatory, if used | E34: float | F34: 20 | G34: 20 | H34: 20 | I34: 20
A35: ev2_daysinweek | B35: days of week where EV is charged (1: Monday, 7: Sunday) | C35: comma-separated list of values between 1..7 (1=Monday), e.g. '1,2,3,4,5' | D35: obligatory, if used | E35: str | F35: 6 | G35: 6 | H35: 6 | I35: 6
A36: ev2_chargetype | B36: charging type: can be fast (with maximum power), flat (constant within period) or optimized (cost-optimized, s.t. battery is full when car leaves charger) | D36: obligatory, if used | E36: str | F36: fast | G36: fast | H36: fast | I36: fast
A37: ev3_max_p | B37: maximum power of charging process | C37: kW | D37: obligatory, if used | E37: float | F37: 20 | G37: 20 | H37: 20 | I37: 20
A38: ev3_period | B38: period when EV is connected to charging column, e.g. 18 - 7 | D38: obligatory, if used | E38: str | F38: 18-7 | G38: 18-7 | H38: 18-7 | I38: 18-7
A39: ev3_drivedist | B39: distance driven with one charge | C39: km | D39: obligatory, if used | E39: float | F39: 50 | G39: 50 | H39: 50 | I39: 50
A40: ev3_kwhper100km | B40: average consumption of electric vehicle | C40: kWh/100km | D40: obligatory, if used | E40: float | F40: 20 | G40: 20 | H40: 20 | I40: 20
...

Sheet Building Data
A1: =Location!A1 -> PARAMETERS | F1: =Location!F1 -> SCENARIO VALUES
A2: name | B2: description | C2: unit | D2: comment | E2: datatype | F2: =Location!F2 -> BAU | G2: =Location!G2 -> PV + HP | H2: =Location!H2 -> Refurbished | I2: =Location!I2 -> Flex
A3: General Data
A4: building_type | B4: multi family home or single family home | C4: - | D4: MFH or SFH | E4: str | F4: MFH | G4: MFH | H4: MFH | I4: MFH
A5: heated_area | B5: floor area of heated rooms | C5: m^2 | E5: float | F5: 370 | G5: 370 | H5: 370 | I5: 370
A6: heated_volume | B6: volume of heated rooms | C6: m^3 | D6: approx. floor_area*room height | E6: float | F6: =F5*2.6 -> 962 | G6: =G5*2.6 -> 962 | H6: =H5*2.6 -> 962 | I6: =I5*2.6 -> 962
A7: vent_rate | B7: ventilation rate | C7: m^3/h | D7: vent_rate = heated_volume * 0.76 if SFH / 0.8 if MFH | E7: float | F7: =F6*(IF(F4="SFH",0.76,0.8)) -> 769.6 | G7: =G6*(IF(G4="SFH",0.76,0.8)) -> 769.6 | H7: =H6*(IF(H4="SFH",0.76,0.8)) -> 769.6 | I7: =I6*(IF(I4="SFH",0.76,0.8)) -> 769.6
A8: air_conditioning | B8: is there automated ventilation? | C8: bool | E8: float | F8: 0 | G8: 0 | H8: 0 | I8: 0
A9: heat_recovery_factor | B9: fraction of heat that is recovered during ventilation | C9: - | E9: float | F9: 0.8 | G9: 0.8 | H9: 0.8 | I9: 0.8
A10: air_change | B10: energy-effective air change rate | C10: - | E10: float | F10: =IF(F8=1,0.4,0.5)*(1-IF(F8=1,F9,0)+0.04) -> 0.52 | G10: =IF(G8=1,0.4,0.5)*(1-IF(G8=1,G9,0)+0.04) -> 0.52 | H10: =IF(H8=1,0.4,0.5)*(1-IF(H8=1,H9,0)+0.04) -> 0.52 | I10: =IF(I8=1,0.4,0.5)*(1-IF(I8=1,I9,0)+0.04) -> 0.52
A11: internal_gains | B11: internal gains by appliances and persons | C11: kW | E11: float | F11: =IF(F4="SFH",50,100)/24*F5/1000 -> 1.5416667 | G11: =IF(G4="SFH",50,100)/24*G5/1000 -> 1.5416667 | H11: =IF(H4="SFH",50,100)/24*H5/1000 -> 1.5416667 | I11: =IF(I4="SFH",50,100)/24*I5/1000 -> 1.5416667
A12: transm_loss | B12: transmission losses through building envelope | C12: kW/K | D12: needs to be given if heat demand is not given | E12: float
A13: ref_heat_load | B13: reference heat load (Normheizlast) | C13: kW | D13: is calculated using transmission losses if not given | E13: float
A14: wall_volume | B14: volume of walls / other components with thermal capacity | C14: m^3 | D14: is used for calculating thermal inertia; outer walls only count half! | E14: float | F14: 100 | G14: 100 | H14: 100 | I14: 100
A15: wall_th_cap | B15: avg. thermal capacity of walls | C15: J/(kg*K) | D15: default 800 | E15: float | F15: 800 | G15: 800 | H15: 800 | I15: 800
A16: wall_density | B16: avg. density of the walls | C16: kg/m^3 | D16: default 1500 | E16: float | F16: 1500 | G16: 1500 | H16: 1500 | I16: 1500
A17: wall_c_eff | B17: effective thermal capacity of building volume (c_wirk) | C17: Wh/(m^3K) | D17: < 50 light, 50 - 130 middle, > 130 heavy | E17: float | F17: =(F14*F15*F16)/3600/F6 -> 34.650035 | G17: =(G14*G15*G16)/3600/G6 -> 34.650035 | H17: =(H14*H15*H16)/3600/H6 -> 34.650035 | I17: =(I14*I15*I16)/3600/I6 -> 34.650035
A18: Windows (to calculate solar gains) and Solar Potential Data
A19: wall1_surface_azimuth | B19: wall orientation | C19: ° | D19: 0° is North, 90° is East, 180° is South, 270° is West | E19: int | F19: 225 | G19: 225 | H19: 225 | I19: 225
A20: wall1_surface_tilt | B20: tilt of wall | C20: ° | D20: 0° is horizontal, 90° is vertical; for flat roofs (=0°) PV systems will be mounted with 10° E-W | E20: int | F20: 90 | G20: 90 | H20: 90 | I20: 90
A21: wall1_window_area_m2 | B21: area of total windows in wall | C21: m^2 | E21: float | F21: 10 | G21: 10 | H21: 10 | I21: 10
A22: wall1_window_g_val | B22: g-value of windows (averaged) | C22: - | D22: 0 … 1 | E22: float | F22: 0.75 | G22: 0.75 | H22: 0.75 | I22: 0.75
A23: wall1_solar_pot_area_m2 | B23: potential area for PV or solarthermal use | C23: m^2 | E23: float | F23: 0 | G23: 0 | H23: 0 | I23: 0
A24: wall1_horizon | B24: horizon profile in °, e.g. "0,0,0,20,40,60,40,30,0". if nothing is given, horizon is assumed to be at 0° | C24: ° | D24: see PVGIS documentation on 'userhorizon' | E24: str | F24: 0,10,20,10,0 | G24: 0,10,20,10,0 | H24: 0,10,20,10,0 | I24: 0,10,20,10,0
A25: wall 2
A26: wall2_surface_azimuth | B26: wall orientation | C26: ° | D26: 0° is North, 90° is East, 180° is South, 270° is West | E26: int | F26: 135 | G26: 135 | H26: 135 | I26: 135
A27: wall2_surface_tilt | B27: tilt of wall | C27: ° | D27: 0° is horizontal, 90° is vertical; for flat roofs (=0°) PV systems will be mounted with 10° E-W | E27: int | F27: 90 | G27: 90 | H27: 90 | I27: 90
A28: wall2_window_area_m2 | B28: area of total windows in wall | C28: m^2 | E28: float | F28: 10 | G28: 10 | H28: 10 | I28: 10
A29: wall2_window_g_val | B29: g-value of windows (averaged) | C29: - | D29: 0 … 1 | E29: float | F29: 0.75 | G29: 0.75 | H29: 0.75 | I29: 0.75
A30: wall2_solar_pot_area_m2 | B30: potential area for PV or solarthermal use | C30: m^2 | E30: float | F30: 0 | G30: 0 | H30: 0 | I30: 0
A31: wall2_horizon | B31: horizon profile in °, e.g. "0,0,0,20,40,60,40,30,0". if nothing is given, horizon is assumed to be at 0° | C31: ° | D31: see PVGIS documentation on 'userhorizon' | E31: str
A32: wall 3
A33: wall3_surface_azimuth | B33: wall orientation | C33: ° | D33: 0° is North, 90° is East, 180° is South, 270° is West | E33: int
A34: wall3_surface_tilt | B34: tilt of wall | C34: ° | D34: 0° is horizontal, 90° is vertical; for flat roofs (=0°) PV systems will be mounted with 10° E-W | E34: int
A35: wall3_window_area_m2 | B35: area of total windows in wall | C35: m^2 | E35: float
A36: wall3_window_g_val | B36: g-value of windows (averaged) | C36: - | D36: 0 … 1 | E36: float
A37: wall3_solar_pot_area_m2 | B37: potential area for PV or solarthermal use | C37: m^2 | E37: float
A38: wall3_horizon | B38: horizon profile in °, e.g. "0,0,0,20,40,60,40,30,0". if nothing is given, horizon is assumed to be at 0° | C38: ° | D38: see PVGIS documentation on 'userhorizon' | E38: str
A39: wall 4
A40: wall4_surface_azimuth | B40: wall orientation | C40: ° | D40: 0° is North, 90° is East, 180° is South, 270° is West | E40: int
...

Sheet Technical Component Data
A1: =Location!A1 -> PARAMETERS | F1: =Location!F1 -> SCENARIO VALUES
A2: name | B2: description | C2: unit | D2: comment | E2: datatype | F2: =Location!F2 -> BAU | G2: =Location!G2 -> PV + HP | H2: =Location!H2 -> Refurbished | I2: =Location!I2 -> Flex
A3: Photovoltaic System
A4: pv1_mount_comp | B4: Area of building where PV system is mounted | C4: - | D4: roof1 ..4, wall1…4 | E4: str | F4: roof1 | G4: roof1 | H4: roof1 | I4: roof1
A5: pv1_kwp_per_m2 | B5: module efficiency | C5: % | D5: typically 20-25% | E5: float | F5: 0.23 | G5: 0.23 | H5: 0.23 | I5: 0.23
A6: pv1_lifetime | B6: expected lifetime of product | C6: a | D6: in years | E6: int | F6: 25 | G6: 25 | H6: 25 | I6: 25
A7: pv1_inv_cost | B7: investment costs | C7: €/kWp | D7: typically 1200 - 1900 €/kWp | E7: float | F7: 870 | G7: 870 | H7: 870 | I7: 870
A8: pv1_fix_cost_inv | B8: investment costs independent of installed capacity | C8: €/invest | E8: float | F8: 5000 | G8: 5000 | H8: 5000 | I8: 5000
A9: pv1_fix_cost_one_time | B9: fix costs at first installation | C9: € | D9: e.g. costs for meter change, electrical installation | E9: float | F9: 12000 | G9: 12000 | H9: 12000 | I9: 12000
A10: pv1_fix_cost_yearly | B10: fix costs every year | C10: €/a | D10: e.g. costs for maintenance, cleaning | E10: float | F10: 0 | G10: 0 | H10: 0 | I10: 0
A11: pv1_p_max | B11: maximum installable capacity | C11: kWp | D11: default 1000 kW, actual potential is calculated using the solar potential area (Building Data) | E11: float | F11: 0 | G11: 21.6 | H11: 21.6 | I11: 21.6
A12: pv1_p_min | B12: minimum installable capacity | C12: kWp | E12: float | F12: 0 | G12: 17.8 | H12: 17.8 | I12: 17.8
A13: pv1_co2eq_per_cap | B13: carbon intensity of life cycle | C13: kg CO2 eq. / kWp | D13: default 800 | E13: float | F13: 800 | G13: 800 | H13: 800 | I13: 800
A14: PV 2
A15: pv2_mount_comp | B15: Area of building where PV system is mounted | C15: - | D15: roof1 ..4, wall1…4 | E15: str | F15: roof1 | G15: roof1 | H15: roof1 | I15: roof1
A16: pv2_kwp_per_m2 | B16: module efficiency | C16: % | D16: typically 20-25% | E16: float | F16: 0.23 | G16: 0.23 | H16: 0.23 | I16: 0.23
A17: pv2_lifetime | B17: expected lifetime of product | C17: a | D17: in years | E17: int | F17: 25 | G17: 25 | H17: 25 | I17: 25
A18: pv2_inv_cost | B18: investment costs | C18: €/kWp | D18: typically 1200 - 1900 €/kWp | E18: float | F18: 870 | G18: 870 | H18: 870 | I18: 870
A19: pv2_fix_cost_inv | B19: investment costs independent of installed capacity | C19: €/invest | E19: float | F19: 1500 | G19: 1500 | H19: 1500 | I19: 1500
A20: pv2_fix_cost_one_time | B20: fix costs at first installation | C20: € | D20: e.g. costs for meter change, electrical installation | E20: float | F20: 0 | G20: 0 | H20: 0 | I20: 0
A21: pv2_fix_cost_yearly | B21: fix costs every year | C21: €/a | D21: e.g. costs for maintenance, cleaning | E21: float | F21: 0 | G21: 0 | H21: 0 | I21: 0
A22: pv2_p_max | B22: maximum installable capacity | C22: kWp | D22: default 1000 kW, actual potential is calculated using the solar potential area (Building Data) | E22: float | F22: 0 | G22: 3.8 | H22: 3.8 | I22: 3.8
A23: pv2_p_min | B23: minimum installable capacity | C23: kWp | E23: float | F23: 0 | G23: 0 | H23: 0 | I23: 0
A24: pv2_co2eq_per_cap | B24: carbon intensity of life cycle | C24: kg CO2 eq. / kWp | D24: default 800 | E24: float | F24: 800 | G24: 800 | H24: 800 | I24: 800
A25: PV 3
A26: pv3_mount_comp | B26: Area of building where PV system is mounted | C26: - | D26: roof1 ..4, wall1…4 | E26: str | F26: roof2 | G26: roof2 | H26: roof2 | I26: roof2
A27: pv3_kwp_per_m2 | B27: module efficiency | C27: % | D27: typically 20-25% | E27: float | F27: 0.23 | G27: 0.23 | H27: 0.23 | I27: 0.23
A28: pv3_lifetime | B28: expected lifetime of product | C28: a | D28: in years | E28: int | F28: 25 | G28: 25 | H28: 25 | I28: 25
A29: pv3_inv_cost | B29: investment costs | C29: €/kWp | D29: typically 1200 - 1900 €/kWp | E29: float | F29: 870 | G29: 870 | H29: 870 | I29: 870
A30: pv3_fix_cost_inv | B30: investment costs independent of installed capacity | C30: €/invest | E30: float | F30: 1500 | G30: 1500 | H30: 1500 | I30: 1500
A31: pv3_fix_cost_one_time | B31: fix costs at first installation | C31: € | D31: e.g. costs for meter change, electrical installation | E31: float | F31: 0 | G31: 0 | H31: 0 | I31: 0
A32: pv3_fix_cost_yearly | B32: fix costs every year | C32: €/a | D32: e.g. costs for maintenance, cleaning | E32: float | F32: 0 | G32: 0 | H32: 0 | I32: 0
A33: pv3_p_max | B33: maximum installable capacity | C33: kWp | D33: default 1000 kW, actual potential is calculated using the solar potential area (Building Data) | E33: float | F33: 0 | G33: 3.2 | H33: 3.2 | I33: 3.2
A34: pv3_p_min | B34: minimum installable capacity | C34: kWp | E34: float | F34: 0 | G34: 0 | H34: 0 | I34: 0
A35: pv3_co2eq_per_cap | B35: carbon intensity of life cycle | C35: kg CO2 eq. / kWp | D35: default 800 | E35: float | F35: 800 | G35: 800 | H35: 800 | I35: 800
A36: PV 4
A37: pv4_mount_comp | B37: Area of building where PV system is mounted | C37: - | D37: roof1 ..4, wall1…4 | E37: str
A38: pv4_kwp_per_m2 | B38: module efficiency | C38: % | D38: typically 20-25% | E38: float
A39: pv4_lifetime | B39: expected lifetime of product | C39: a | D39: in years | E39: int
A40: pv4_inv_cost | B40: investment costs | C40: €/kWp | D40: typically 1200 - 1900 €/kWp | E40: float
...

Sheet Economic Data
A1: =Location!A1 -> PARAMETERS | F1: =Location!F1 -> SCENARIO VALUES
A2: name | B2: description | C2: unit | D2: comment | E2: datatype | F2: =Location!F2 -> BAU | G2: =Location!G2 -> PV + HP | H2: =Location!H2 -> Refurbished | I2: =Location!I2 -> Flex
A3: General Economic Data
A4: real_interest_rate | B4: interest rate | C4: % | D4: real interest rate | E4: float | F4: 0.02 | G4: 0.02 | H4: 0.02 | I4: 0.02
A5: duration | B5: duration of modelling period | C5: years | D5: period to be modelled | E5: float | F5: 30 | G5: 30 | H5: 30 | I5: 30
A6: Electricity Prices
A7: el_hh_kwh_rate | B7: flat tariff for households | C7: ct/kWh | D7: volumetric price component | E7: float | F7: 35 | G7: 35 | H7: 35 | I7: 35
A8: el_hh_basic_charge | B8: basic monthly charge independent of consumption | C8: €/month | D8: basic monthly charge | E8: float | F8: 50 | G8: 50 | H8: 50 | I8: 50
A9: el_hh_is_dynamic_tariff | B9: decision variable if flat tariff is applied | C9: bool | D9: dynamic tariff is automatically calculated based on EEX-prices, kwh rates and basic charges are applied additionally | E9: bool | F9: 0 | G9: 0 | H9: 0 | I9: 0
A10: el_hh_var_grid_fees | B10: decision variable if flat tariff is applied | C10: bool | D10: decision variable for applying variable grid fees (EnWG 14a) | E10: bool | F10: 0 | G10: 0 | H10: 0 | I10: 0
A11: el_hh_grid_to_battery | B11: decision variable if flat tariff is applied | C11: bool | D11: decision variable whether battery can be charged with electricity from grid | E11: bool | F11: 0 | G11: 0 | H11: 0 | I11: 0
A12: el_hp_kwh_rate | B12: flat tariff for households | C12: ct/kWh | D12: volumetric price component | E12: float | F12: 35 | G12: 35 | H12: 35 | I12: 5
A13: el_hp_basic_charge | B13: basic monthly charge independent of consumption | C13: €/month | D13: basic monthly charge | E13: float | F13: 0 | G13: 0 | H13: 0 | I13: 12
A14: el_hp_is_dynamic_tariff | B14: decision variable if flat tariff is applied | C14: bool | D14: dynamic tariff is automatically calculated based on EEX-prices, kwh rates and basic charges are applied additionally | E14: bool | F14: 0 | G14: 0 | H14: 0 | I14: 1
A15: el_hp_var_grid_fees | B15: decision variable if flat tariff is applied | C15: bool | D15: decision variable for applying variable grid fees (EnWG 14a) | E15: bool | F15: 0 | G15: 0 | H15: 0 | I15: 1
A16: el_hp_grid_to_battery | B16: decision variable if flat tariff is applied | C16: bool | D16: decision variable whether battery can be charged with electricity from grid | E16: bool | F16: 0 | G16: 0 | H16: 0 | I16: 1
A17: el_emob_kwh_rate | B17: flat tariff for households | C17: ct/kWh | D17: volumetric price component | E17: float | F17: 35 | G17: 35 | H17: 35 | I17: 5
A18: el_emob_basic_charge | B18: basic monthly charge independent of consumption | C18: €/month | D18: basic monthly charge | E18: float | F18: 0 | G18: 0 | H18: 0 | I18: 12
... A23: el_feedin_is_directly_marketed | B23: decision variable whether direct marketing condisitons are applied | C23: bool | D23: if feed-in is directly marketed, feed-in revenues are calculated by EEX-market data | E23: float | F23: 0 | G23: 0 | H23: 0 | I23: 1
A24: CO2 Price
A25: co2_price | B25: CO2-price | C25: €/ton | D25: In 2025: 55€/t, in 2026: 55-65€/t, from 2027 on cap and trade (expectations of 100 - 200€/t | E25: float | F25: 100 | G25: 100 | H25: 100 | I25: 100
A26: (Variable) Grid Fees (EnWG 14a)
A27: grid_fees_st | B27: standarf tariff | C27: ct/kWh | D27: e.g. 10ct/kWh | E27: float | F27: 10 | G27: 10 | H27: 10 | I27: 8.5
A28: tvg_lt_summer | B28: low tariff | C28: ct/kWh | D28: e.g. 20ct/kWh | E28: float
A29: tvg_lt_windows_summer | B29: low tariff window | C29: h | D29: HH-HH separated by comma e.g. "8-9,17-20" | E29: str
A30: tvg_ht_summer | B30: high tariff | C30: ct/kWh | D30: e.g. 20ct/kWh | E30: float
A31: tvg_ht_windows_summer | B31: high tariff window | C31: h | D31: HH-HH separated by comma e.g. "8-9,17-20" | E31: str
A32: tvg_lt_transition | B32: low tariff | C32: ct/kWh | D32: e.g. 20ct/kWh | E32: float | I32: 3.1
A33: tvg_lt_windows_transition | B33: low tariff window | C33: h | D33: HH-HH separated by comma e.g. "8-9,17-20" | E33: str | I33: 0-6
A34: tvg_ht_transition | B34: high tariff | C34: ct/kWh | D34: e.g. 20ct/kWh | E34: float | I34: 11.9
A35: tvg_ht_windows_transition | B35: high tariff window | C35: h | D35: HH-HH separated by comma e.g. "8-9,17-20" | E35: str | I35: 17-20
A36: tvg_lt_winter | B36: low tariff | C36: ct/kWh | D36: e.g. 20ct/kWh | E36: float | I36: 3.1
A37: tvg_lt_windows_winter | B37: low tariff window | C37: h | D37: HH-HH separated by comma e.g. "8-9,17-20" | E37: str | I37: 0-6
A38: tvg_ht_winter | B38: high tariff | C38: ct/kWh | D38: e.g. 20ct/kWh | E38: float | I38: 11.9
A39: tvg_ht_windows_winter | B39: high tariff window | C39: h | D39: HH-HH separated by comma e.g. "8-9,17-20" | E39: str | I39: 17-20

Sheet Model Settings
A1: =Location!A1 -> PARAMETERS | F1: =Location!F1 -> SCENARIO VALUES
A2: name | B2: description | C2: unit | D2: comment | E2: datatype | F2: =Location!F2 -> BAU | G2: =Location!G2 -> PV + HP | H2: =Location!H2 -> Refurbished | I2: =Location!I2 -> Flex
A3: modeled_year | B3: year that is modeled | C3: a | D3: must be in the range of 2019 - 2023 | E3: int | F3: 2023 | G3: 2023 | H3: 2023 | I3: 2023
A4: apply_timeseries_reduction | B4: timeseries reduction reduces year to one typical refernce week per season | C4: bool | D4: for performance reasons timeseries reduction is recommended | E4: bool | F4: 1 | G4: 1 | H4: 1 | I4: 1

Sheet HP Specifications
A1: INDEX | D1: VALUES
A2: hp_type | B2: param | C2: flow_temp | D2: -20 | E2: -15 | F2: -10 | G2: -7 | H2: 2 | I2: 7 | J2: 10 | K2: 20 | L2: 30 | M2: 35
A3: {=Tabelle5[hp_types_air_water]} -> vitocal_250A | B3: COP | C3: 25 | D3: 2.6 | E3: 2.8 | F3: 3.2 | G3: 3.4 | H3: 4.5 | I3: 5.8 | J3: 5.8 | K3: 8.4 | L3: 8.7 | M3: 8.7
A4: {=Tabelle5[hp_types_air_water]} -> vitocal_250A | B4: COP | C4: 35 | D4: 2.3 | E4: 2.5 | F4: 2.8 | G4: 3 | H4: 4 | I4: 5.2 | J4: 5.2 | K4: 8.2 | L4: 8.7 | M4: 8.7
A5: {=Tabelle5[hp_types_air_water]} -> vitocal_250A | B5: COP | C5: 45 | D5: 2 | E5: 2.2 | F5: 2.4 | G5: 2.6 | H5: 3.3 | I5: 4.1 | J5: 4.8 | K5: 5.4 | L5: 8.5 | M5: 8.5
A6: {=Tabelle5[hp_types_air_water]} -> vitocal_250A | B6: COP | C6: 55 | D6: 1.8 | E6: 2 | F6: 2.2 | G6: 2.3 | H6: 2.8 | I6: 3.4 | J6: 3.7 | K6: 4.8 | L6: 6.4 | M6: 6.4
A7: {=Tabelle5[hp_types_air_water]} -> vitocal_250A | B7: COP | C7: 65 | D7: 1.6 | E7: 1.8 | F7: 2 | G7: 2.1 | H7: 2.5 | I7: 2.8 | J7: 3 | K7: 3.7 | L7: 4.7 | M7: 4.7
A8: {=Tabelle5[hp_types_air_water]} -> vitocal_250A | B8: COP | C8: 70 | D8: 0 | E8: 0 | F8: 1.8 | G8: 1.9 | H8: 2.3 | I8: 2.6 | J8: 2.7 | K8: 3.3 | L8: 4.1 | M8: 4.1
A9: {=Tabelle5[hp_types_air_water]} -> vitocal_250A | B9: Qmax | C9: 25 | D9: 0.75 | E9: 0.85 | F9: 0.97 | G9: 1.04 | H9: 0.62 | I9: 0.76 | J9: 0.84 | K9: 1.09 | L9: 0.86 | M9: 0.86
A10: {=Tabelle5[hp_types_air_water]} -> vitocal_250A | B10: Qmax | C10: 35 | D10: 0.7 | E10: 0.8 | F10: 0.93 | G10: 1 | H10: 0.6 | I10: 0.73 | J10: 0.79 | K10: 1.05 | L10: 1.08 | M10: 1.08
A11: {=Tabelle5[hp_types_air_water]} -> vitocal_250A | B11: Qmax | C11: 45 | D11: 0.66 | E11: 0.76 | F11: 0.88 | G11: 0.96 | H11: 0.59 | I11: 0.7 | J11: 0.75 | K11: 1 | L11: 1.3 | M11: 1.3
A12: {=Tabelle5[hp_types_air_water]} -> vitocal_250A | B12: Qmax | C12: 55 | D12: 0.63 | E12: 0.75 | F12: 0.87 | G12: 0.95 | H12: 0.58 | I12: 0.68 | J12: 0.75 | K12: 1.01 | L12: 1.31 | M12: 1.31
A13: {=Tabelle5[hp_types_air_water]} -> vitocal_250A | B13: Qmax | C13: 65 | D13: 0.41 | E13: 0.55 | F13: 0.72 | G13: 0.82 | H13: 0.57 | I13: 0.68 | J13: 0.75 | K13: 0.99 | L13: 1.26 | M13: 1.26
A14: {=Tabelle5[hp_types_air_water]} -> vitocal_250A | B14: Qmax | C14: 70 | D14: 0 | E14: 0 | F14: 0.54 | G14: 0.62 | H14: 0.57 | I14: 0.68 | J14: 0.75 | K14: 0.98 | L14: 1.25 | M14: 1.25
A15: =Definitions!E2 -> bosch_ClimateClass8000i | B15: COP | C15: 20 | D15: 0 | E15: 2.8 | F15: 3 | G15: 3.5 | H15: 5.1 | I15: 6.2 | J15: =I15+(K15-I15)*($J$2-$I$2)/($K$2-$I$2) -> 6.6153846 | K15: 8 | L15: 0 | M15: 0
A16: =Definitions!E2 -> bosch_ClimateClass8000i | B16: Qmax | C16: 20 | D16: 0 | E16: 1 | F16: 1.12 | G16: 1 | H16: 0.6 | I16: 0.44 | J16: =I16+(K16-I16)*($J$2-$I$2)/($K$2-$I$2) -> 0.44923077 | K16: 0.48 | L16: 0 | M16: 0

Sheet Definitions
A1: building_type | B1: building_area_components | C1: st_collector_types | D1: hp_types_air_water | E1: ac_types | F1: charging_type | G1: dhw_l_per_person
A2: MFH | B2: roof1 | C2: absorber | D2: vitocal_250A | E2: bosch_ClimateClass8000i | F2: fast | G2: 30
A3: SFH | B3: roof2 | C3: flatplate_singlecover_nonsel | F3: flat | G3: 40
B4: roof3 | C4: flatplate_singlecover_sel | F4: optimized | G4: 50
B5: roof4 | C5: flatplate_singlecover_nonsel
B6: wall1 | C6: vacuumtube
B7: wall2
B8: wall3
B9: wall4
